<?xml version="1.0" ?>

<!-- Robot name -->
<robot name="bicycle_robot" xmlns:xacro="http://ros.org/wiki/xacro">

    <!-- Base Link of Robot -->
    <link name="base_link">
    </link>

    <!-- Link of Body -->
    <link name="body">
        <visual>
            <origin rpy="0 0 0" xyz="0 0 0"/>
                <geometry>
                    <mesh filename="package://ugv_assign_description/meshes/Body.stl"/>
                </geometry>
        </visual>

        <collision>
            <origin rpy="0 0 0" xyz="0 0 0"/>
                <geometry>
                    <mesh filename="package://ugv_assign_description/meshes/Body.stl"/>
                </geometry>
        </collision>

        <inertial>
            <origin rpy="0 0 0" xyz="0.243139 0.0 0.28823924"/>
            <!-- <mass value="27.07252378"/> -->
            <mass value="80"/>
            <inertia ixx="3.972233197" ixy="0.0" ixz="0.0" iyx = "0.0" iyy="7.985929675" iyz ="0.0" izx="0.0" izy="0.0" izz="4.813503322"/>
        </inertial>
    </link>

    <!-- Joint connecting base link and body -->
    <joint name="base_link_joint" type="fixed">
        <parent link="base_link"/>
        <child link="body"/>
        <origin rpy="0 0 0" xyz="0 0 0" />
    </joint>


    <!-- Link of Handlebars -->
    <link name="handlebars">
        <visual>
            <origin rpy="0 0 0" xyz="0 0 0"/>
                <geometry>
                    <mesh filename="package://ugv_assign_description/meshes/Handlebars.stl"/>
                </geometry>
        </visual>

        <collision>
            <origin rpy="0 0.0 0" xyz="0 0 0"/>
                <geometry>
                    <mesh filename="package://ugv_assign_description/meshes/Handlebars.stl"/>
                </geometry>
        </collision>

        <inertial>
            <origin rpy="0 0.0 0" xyz="0 0 0"/>
            <mass value="12.90945896"/>
            <inertia ixx="0.819980734" ixy="0.0" ixz="0.0" iyx = "0.0" iyy="0.518852099" iyz ="0.0"  izx="0.0" izy="0.0" izz="0.368397616"/>
        </inertial>
    </link>

    <!-- Handlebars joint -->
    <joint name="handlebars_joint" type="revolute">
        <parent link="body"/>
        <child link="handlebars"/>
        <origin rpy="0 -0.436549886 0" xyz="0.51742583 0.0 0.53743702"/>
        <axis xyz = "0 0 1"/>
        <limit lower = "-0.5" upper = "0.5" effort = "10.0" velocity = "5.0" />
    </joint>

    <!-- Handlebars transmission -->
    <transmission name="steer_joint_trans">
      <type>transmission_interface/SimpleTransmission</type>
      <actuator name="steer_joint_motor">
        <mechanicalReduction>1</mechanicalReduction>
        <hardwareInterface>hardware_interface/PositionJointInterface</hardwareInterface>
      </actuator>
      <joint name="handlebars_joint">
        <hardwareInterface>hardware_interface/PositionJointInterface</hardwareInterface>
      </joint>
    </transmission>

    <!-- Front Suspension Link -->
   <link name="front_suspension">
        <visual>
            <origin rpy="0 0 0" xyz="0 0 0"/>
                <geometry>
                    <mesh filename="package://ugv_assign_description/meshes/Front_Suspension.stl"/>
                </geometry>
        </visual>

        <collision>
            <origin rpy="0 0 0" xyz="0 0 0"/>
                <geometry>
                    <mesh filename="package://ugv_assign_description/meshes/Front_Suspension.stl"/>
                </geometry>
        </collision>

        <inertial>
            <origin rpy="0 0 0" xyz="0 0 0"/>
            <mass value="7.78054865"/>
            <inertia ixx="0.18819038" ixy="0.0" ixz="0.0" iyx = "0.0" iyy="0.11650317" iyz ="0.0"  izx="0.0" izy="0.0" izz="0.08405421"/>
        </inertial>
    </link>

    <!-- Front Suspension Joint -->
    <joint name="front_suspension_joint" type="prismatic">
        <parent link="handlebars"/>
        <child link="front_suspension"/>
        <origin rpy="0 0 0" xyz="0.00717323 0.0 -0.45356114" />
        <axis xyz = "0 0 1" />
        <limit lower = "0.0" upper = "0.165" effort = "50.0" velocity = "1.0" />
        <dynamics damping = "8000" friction = "8000"/>
    </joint>

    <!-- Front Suspension Transmission -->
    <transmission name="front_suspension_joint_trans">
      <type>transmission_interface/SimpleTransmission</type>
      <actuator name="front_suspension_joint_motor">
        <mechanicalReduction>1</mechanicalReduction>
        <hardwareInterface>hardware_interface/EffortJointInterface</hardwareInterface>
      </actuator>
      <joint name="front_suspension_joint">
        <hardwareInterface>hardware_interface/EffortJointInterface</hardwareInterface>
      </joint>
    </transmission>

    <!-- Front Wheel Link -->
   <link name="front_wheel">
        <visual>
            <origin rpy="0 0 0" xyz="0 0 0"/>
                <geometry>
                    <mesh filename="package://ugv_assign_description/meshes/Wheel.stl"/>
                </geometry>
        </visual>

        <collision>
            <origin rpy="0 0 0" xyz="0 0 0"/>
                <geometry>
                    <mesh filename="package://ugv_assign_description/meshes/Wheel.stl"/>
                </geometry>
        </collision>

        <inertial>
            <origin rpy="0 0 0" xyz="0 0 0"/>
            <mass value="12"/>
            <inertia ixx="1.055546716" ixy="0" ixz="0" iyx = "0" iyy="2.057926575" iyz ="0.0"  izx="0" izy="0" izz="1.055546716"/>
        </inertial>
    </link>

    <!-- Front Wheel Joint -->
    <joint name="front_wheel_joint" type="continuous">
        <parent link="front_suspension"/>
        <child link="front_wheel"/>
        <origin rpy="0 0.436549886 0" xyz="0.05546002 0 -0.16877486" />
        <axis xyz="0 1 0" />
        <dynamics damping = "20" friction = "20" />
    </joint>


    <!-- Link of Back Body -->
    <link name="back_body">
        <visual>
            <origin rpy="0 0 0" xyz="0 0 0"/>
                <geometry>
                    <mesh filename="package://ugv_assign_description/meshes/Back_Body.stl"/>
                </geometry>
        </visual>

        <collision>
            <origin rpy="0 0 0" xyz="0 0 0"/>
                <geometry>
                    <mesh filename="package://ugv_assign_description/meshes/Back_Body.stl"/>
                </geometry>
        </collision>

        <inertial>
            <origin rpy="0 0 0" xyz="-0.25658211 0.0 -0.00000005172"/>
            <mass value="30"/>
            <inertia ixx="0.17410128" ixy="0.0" ixz="-0.0000001204" iyx = "0.0" iyy="0.39381739" iyz ="0.0" izx="-0.0000001204" izy="0.0" izz="0.5492687"/>
        </inertial>
    </link>

    <!-- Joint connecting both bodies -->
    <joint name="back_body_joint" type="fixed">
        <parent link="body"/>
        <child link="back_body"/>
        <origin rpy="0 0 0" xyz="0 0 0" />
    </joint>


    <!-- Rear Wheel Link -->
   <link name="rear_wheel">
        <visual>
            <origin rpy="0 0 0" xyz="0 0 0"/>
                <geometry>
                    <mesh filename="package://ugv_assign_description/meshes/Wheel.stl"/>
                </geometry>
        </visual>

        <collision>
            <origin rpy="0 0 0" xyz="0 0 0"/>
                <geometry>
                    <mesh filename="package://ugv_assign_description/meshes/Wheel.stl"/>
                </geometry>
        </collision>

        <inertial>
            <origin rpy="0 0 0" xyz="0 0 0"/>
            <mass value="20"/>
            <inertia ixx="1.055546716" ixy="0" ixz="0" iyx = "0" iyy="2.057926575" iyz ="0.0"  izx="0" izy="0" izz="1.055546716"/>
        </inertial>
    </link>

    <!-- Rear Wheel Joint -->
    <joint name="rear_wheel_joint" type="continuous">
        <parent link="back_body"/>
        <child link="rear_wheel"/>
        <origin rpy="0 0 0" xyz="-0.43470565 0 0" />
        <axis xyz="0 1 0" />
        <dynamics damping = "2000" friction = "2000" />
    </joint>

    <!-- Rear Wheel Transmission -->
    <transmission name="rear_wheel_joint_trans">
      <type>transmission_interface/SimpleTransmission</type>
      <actuator name="rear_wheel_joint_motor">
        <mechanicalReduction>1</mechanicalReduction>
        <hardwareInterface>hardware_interface/VelocityJointInterface</hardwareInterface>
      </actuator>
      <joint name="rear_wheel_joint">
        <hardwareInterface>hardware_interface/VelocityJointInterface</hardwareInterface>
      </joint>
    </transmission>

    <!-- Link of Middle Body -->
    <link name="middle_body">
        <visual>
            <origin rpy="0 0 0" xyz="0 0 0"/>
                <geometry>
                    <mesh filename="package://ugv_assign_description/meshes/Mini_Wheels_Body.stl"/>
                </geometry>
        </visual>

        <collision>
            <origin rpy="0 0 0" xyz="0 0 0"/>
                <geometry>
                    <mesh filename="package://ugv_assign_description/meshes/Mini_Wheels_Body.stl"/>
                </geometry>
        </collision>

        <inertial>
            <origin rpy="0 0 0" xyz="0.0 0.0 -0.01612632"/>
            <mass value="15"/>
            <inertia ixx="0.18693089" ixy="0.0" ixz="0.0" iyx = "0.0" iyy="0.00688622" iyz ="0.0" izx="0.0" izy="0.0" izz="0.18112334"/>
        </inertial>
    </link>

    <!-- Joint connecting both bodies -->
    <joint name="middle_body_joint" type="fixed">
        <parent link="body"/>
        <child link="middle_body"/>
        <origin rpy="0 0 0" xyz="0 0 0" />
    </joint>

    <!-- Link of Right Middle suspension -->
    <link name="middle_suspension_right">
        <visual>
            <origin rpy="0 0 0" xyz="0 0 0"/>
                <geometry>
                    <mesh filename="package://ugv_assign_description/meshes/Middle_Suspension.stl"/>
                </geometry>
        </visual>

        <collision>
            <origin rpy="0 0 0" xyz="0 0 0"/>
                <geometry>
                    <mesh filename="package://ugv_assign_description/meshes/Middle_Suspension.stl"/>
                </geometry>
        </collision>

        <inertial>
            <!-- <origin rpy="0 0 0" xyz="0.0 -0.225 -0.19859667"/> -->
            <origin rpy="0 0 0" xyz="0 0 0"/>
            <mass value="1"/>
            <inertia ixx="0.0134723" ixy="0.0" ixz="0.0" iyx = "0.0" iyy="0.0134723" iyz ="0.0" izx="0.0" izy="0.0" izz="0.0031567"/>
        </inertial>
    </link>

    <!-- Joint connecting both bodies -->
    <joint name="middle_suspension_right_joint" type="prismatic">
        <parent link="middle_body"/>
        <child link="middle_suspension_right"/>
        <origin rpy="0 0 0" xyz="0 0 0" />
        <axis xyz = "0 0 1" />
        <limit lower = "0.0" upper = "0.05" effort = "50.0" velocity = "0.1" />
        <dynamics damping = "1000" friction = "1000" />
    </joint>

    <transmission name="middle_suspension_right_joint_trans">
      <type>transmission_interface/SimpleTransmission</type>
      <actuator name="middle_suspension_right_joint_motor">
        <mechanicalReduction>1</mechanicalReduction>
        <hardwareInterface>hardware_interface/EffortJointInterface</hardwareInterface>
      </actuator>
      <joint name="middle_suspension_right_joint">
        <hardwareInterface>hardware_interface/EffortJointInterface</hardwareInterface>
      </joint>
    </transmission>

    <!-- Link of left Middle suspension -->
    <link name="middle_suspension_left">
        <visual>
            <origin rpy="0 0 0" xyz="0 0 0"/>
                <geometry>
                    <mesh filename="package://ugv_assign_description/meshes/Middle_Suspension.stl"/>
                </geometry>
        </visual>

        <collision>
            <origin rpy="0 0 0" xyz="0 0 0"/>
                <geometry>
                    <mesh filename="package://ugv_assign_description/meshes/Middle_Suspension.stl"/>
                </geometry>
        </collision>

        <inertial>
            <origin rpy="0 0 0"  xyz="0.0 0 0"/>
            <mass value="15"/>
            <inertia ixx="0.0134723" ixy="0.0" ixz="0.0" iyx = "0.0" iyy="0.0134723" iyz ="0.0" izx="0.0" izy="0.0" izz="0.0031567"/>
        </inertial>
    </link>

    <!-- Joint connecting both bodies -->
    <joint name="middle_suspension_left_joint" type="prismatic">
        <parent link="body"/>
        <child link="middle_suspension_left"/>
        <origin rpy="0 0 3.141592654" xyz="0 0 0" />
        <axis xyz = "0 0 1" />
        <limit lower = "0.0" upper = "0.05" effort = "50.0" velocity = "1.0" />
        <dynamics damping = "1000" friction = "1000" />
    </joint>



    <!-- Middle Wheel Right Link -->
   <link name="middle_wheel_right">
        <visual>
            <origin rpy="0 0 0" xyz="0 0 0"/>
                <geometry>
                    <mesh filename="package://ugv_assign_description/meshes/Mini_Wheels.stl"/>
                </geometry>
        </visual>

        <collision>
            <origin rpy="0 0 0" xyz="0 0 0"/>
                <geometry>
                    <mesh filename="package://ugv_assign_description/meshes/Mini_Wheels.stl"/>
                </geometry>
        </collision>

        <inertial>
            <origin rpy="0 0 0" xyz="0 0 0"/>
            <mass value="5"/>
            <inertia ixx="0.193952475" ixy="0" ixz="0" iyx = "0" iyy="0.382147216" iyz ="0.0"  izx="0" izy="0" izz="0.193949324"/>
        </inertial>
    </link>

    <!-- Middle Wheel Right Joint -->
    <joint name="middle_wheel_right_joint" type="continuous">
        <parent link="middle_suspension_right"/>
        <child link="middle_wheel_right"/>
        <origin rpy="0 0 0" xyz="0 -0.275 -0.22" />
        <axis xyz="0 1 0" />
    </joint>


    <!-- Middle Wheel Left Link -->
   <link name="middle_wheel_left">
        <visual>
            <origin rpy="0 0 0" xyz="0 0 0"/>
                <geometry>
                    <mesh filename="package://ugv_assign_description/meshes/Mini_Wheels.stl"/>
                </geometry>
        </visual>

        <collision>
            <origin rpy="0 0 0" xyz="0 0 0"/>
                <geometry>
                    <mesh filename="package://ugv_assign_description/meshes/Mini_Wheels.stl"/>
                </geometry>
        </collision>

        <inertial>
            <origin rpy="0 0 0" xyz="0 0 0"/>
            <mass value="5"/>
            <inertia ixx="0.193952475" ixy="0" ixz="0" iyx = "0" iyy="0.382147216" iyz ="0.0"  izx="0" izy="0" izz="0.193949324"/>
        </inertial>
    </link>

    <!-- Middle Wheel Left Joint -->
    <joint name="middle_wheel_left_joint" type="continuous">
        <parent link="middle_suspension_left"/>
        <child link="middle_wheel_left"/>
        <origin rpy="0 0 0" xyz="0 -0.275 -0.22" />
        <axis xyz="0 1 0" />
    </joint>

    <!-- SENSORS -->


    <!-- IMU Link -->
   <link name="imu_link">
    </link>

    <!-- IMU Joint -->
    <joint name="imu_joint" type="fixed">
        <parent link="body"/>
        <child link="imu_link"/>
        <origin rpy="0 0 0" xyz="0 0 0" />
    </joint>


    <!-- Camera Support Link -->
   <link name="camera_support">
        <visual>
            <origin rpy="0 0.436549886 0" xyz="0.03568383 0 0.12892733"/>
            <geometry>
                <mesh filename="package://ugv_assign_description/meshes/Camera_Support.stl"/>
            </geometry>
        </visual>

        <collision>
            <origin rpy="0 0 0" xyz="0 0 0"/>
            <geometry>
                <mesh filename="package://ugv_assign_description/meshes/Camera_Support.stl"/>
            </geometry>
        </collision>

    <inertial>
        <origin rpy="0 0 0" xyz="0 0 0"/>
        <mass value="3.4016517"/>
        <inertia ixx="0.00609655" ixy="0" ixz="0" iyx = "0" iyy="0.00871727" iyz ="0.0"  izx="0" izy="0" izz="0.0116844"/>
    </inertial>
    </link>

    <!-- Camera Support Joint -->
    <joint name="camera_support_joint" type="fixed">
        <parent link="handlebars"/>
        <child link="camera_support"/>
        <origin rpy="0 0 0" xyz="0 0 0" />
    </joint>

    <!-- Camera Stereo Link -->
   <link name="camera_stereo">
        <visual>
            <origin rpy="0 0 0" xyz="0 0 0"/>
                <geometry>
                    <mesh filename="package://ugv_assign_description/meshes/Camera_Stereo.stl"/>
                </geometry>
        </visual>

        <collision>
            <origin rpy="0 0 0" xyz="0 0 0"/>
                <geometry>
                    <mesh filename="package://ugv_assign_description/meshes/Camera_Stereo.stl"/>
                </geometry>
        </collision>

    </link>

    <!-- Camera Stereo Joint -->
    <joint name="camera_stereo_joint" type="fixed">
        <parent link="camera_support"/>
        <child link="camera_stereo"/>
        <origin rpy="0 0.436549886 0" xyz="0.15649823 0.08 0.09515994" />
    </joint>

    <!-- Camera Stereo Left Lens -->
    <link name="camera_stereo_left">
    </link>

    <!-- Camera Stereo Left Lens Joint -->
    <joint name="camera_stereo_left_joint" type="fixed">
        <parent link="camera_stereo"/>
        <child link="camera_stereo_left"/>
        <origin rpy="0 0 0" xyz="0 0 0" />
    </joint>

    <!-- Camera Stereo Right Lens -->
    <link name="camera_stereo_right">
    </link>

    <!-- Camera Stereo Right Lens Joint -->
    <joint name="camera_stereo_right_joint" type="fixed">
        <parent link="camera_stereo"/>
        <child link="camera_stereo_right"/>
        <origin rpy="0 0 0" xyz="0 -0.16 0" />
    </joint>


    <!-- Gazebo plugins -->
    <gazebo>
        <plugin name="gazebo_ros_control" filename="libgazebo_ros_control.so">
            <robotNamespace>/bicycle_robot</robotNamespace>
            <legacyModeNS>true</legacyModeNS>
        </plugin>
    </gazebo>

    <gazebo>
        <plugin name="joint_state_publisher" filename="libgazebo_ros_joint_state_publisher.so">
            <jointName>front_wheel_joint,middle_wheel_left_joint,middle_wheel_right_joint,front_suspension_joint</jointName>
            <updateRate>50</updateRate>
        </plugin>
    </gazebo>

    <gazebo reference="imu_link">
    <gravity>true</gravity>
    <sensor name="imu_sensor" type="imu">
      <always_on>true</always_on>
      <update_rate>100</update_rate>
      <visualize>true</visualize>
      <topic>__default_topic__</topic>
      <plugin filename="libgazebo_ros_imu_sensor.so" name="imu_plugin">
        <topicName>imu</topicName>
        <bodyName>imu_link</bodyName>
        <updateRateHZ>50.0</updateRateHZ>
        <gaussianNoise>0.0</gaussianNoise>
        <xyzOffset>0 0 0</xyzOffset>
        <rpyOffset>0 0 0</rpyOffset>
        <frameName>imu_link</frameName>
        <initialOrientationAsReference>false</initialOrientationAsReference>
      </plugin>
      <pose>0 0 0 0 0 0</pose>
    </sensor>
  </gazebo>


  <gazebo reference="camera_stereo_left">
    <sensor type="multicamera" name="stereo_camera">
      <update_rate>30.0</update_rate>
      <camera name="left">
        <horizontal_fov>1.3962634</horizontal_fov>
        <image>
          <width>1280</width>
          <height>720</height>
          <format>R8G8B8</format>
        </image>
        <clip>
          <near>0.02</near>
          <far>50</far>
        </clip>
        <noise>
          <type>gaussian</type>
          <mean>0.0</mean>
          <stddev>0.007</stddev>
        </noise>
      </camera>
      <camera name="right">
        <pose>0 -0.16 0 0 0 0</pose>
        <horizontal_fov>1.3962634</horizontal_fov>
        <image>
          <width>1280</width>
          <height>720</height>
          <format>R8G8B8</format>
        </image>
        <clip>
          <near>0.02</near>
          <far>50</far>
        </clip>
        <noise>
          <type>gaussian</type>
          <mean>0.0</mean>
          <stddev>0.007</stddev>
        </noise>
      </camera>
      <plugin name="stereo_camera_controller" filename="libgazebo_ros_multicamera.so">
        <alwaysOn>true</alwaysOn>
        <updateRate>0.0</updateRate>
        <cameraName>camera</cameraName>
        <imageTopicName>image_raw</imageTopicName>
        <cameraInfoTopicName>camera_info</cameraInfoTopicName>
        <frameName>camera_stereo_left</frameName>
        <hackBaseline>0.07</hackBaseline>
        <distortionK1>0.0</distortionK1>
        <distortionK2>0.0</distortionK2>
        <distortionK3>0.0</distortionK3>
        <distortionT1>0.0</distortionT1>
        <distortionT2>0.0</distortionT2>
      </plugin>
    </sensor>
  </gazebo>


    <!-- Velodyne Link -->
    <link name="bicycle_velodyne">
    </link>

    <!-- Velodyne Joint -->
    <joint name="bicycle_velodyne" type="fixed">
        <parent link="body"/>
        <child link="bicycle_velodyne"/>
        <origin rpy="0 0 0" xyz="0 0 0" />
    </joint>


    <gazebo reference="bicycle_velodyne">
        <sensor type="ray" name="bicycle_velodyne-VLP16">
          <pose>0 0 0 0 0 0</pose>
          <visualize>false</visualize>
          <update_rate>50</update_rate>
          <ray>
            <scan>
              <horizontal>
                <samples>256</samples>
                <resolution>1</resolution>
                <min_angle>-3.141592654</min_angle>
                <max_angle>3.141592654</max_angle>
              </horizontal>
              <vertical>
                <samples>16</samples>
                <resolution>1</resolution>
                <min_angle>-0.261799388</min_angle>
                <max_angle>0.261799388</max_angle>
              </vertical>
            </scan>
            <range>
              <min>0.3</min>
              <max>21.0</max>
              <resolution>0.001</resolution>
            </range>
            <noise>
              <type>gaussian</type>
              <mean>0.0</mean>
              <stddev>0.0</stddev>
            </noise>
          </ray>
          <plugin name="gazebo_ros_laser_controller" filename="libgazebo_ros_velodyne_laser.so">
            <topicName>/velodyne_points</topicName>
            <frameName>bicycle_velodyne</frameName>
            <min_range>0.9</min_range>
            <max_range>20.0</max_range>
            <gaussianNoise>0.008</gaussianNoise>
          </plugin>
        </sensor>
    </gazebo>

</robot>